<robot name="simple_robot">

	<!-- * * * Link Definitions * * * -->

  	<link name="link0"> <!--base_link -->
		<visual>
			<origin xyz="0 0 0" rpy="0 0 0"/>
			<geometry>
				<cylinder radius="0.1" length="0.05"/>
			</geometry>
	     	<material name="Cyan3">
				<color rgba="0 0.5 0.5 0"/>
			</material>
	   </visual>
	</link>

  	<link name="link1"> <!-- cylinder0 -->
		<visual>
			<origin xyz="0 0 0" rpy="0 0 0"/>
			<geometry>
				<cylinder radius="0.05" length="0.2"/>
			</geometry>
	     	<material name="Yellow2">
				<color rgba="0.8 0.8 0 1.0"/>
			</material>
	   </visual>
	</link>	
		
	<link name="link2"> <!-- ball0 -->
		<visual>
			<origin xyz="0 0 0" rpy="0 0 0"/>
			<geometry>
				<sphere radius="0.052"/>
			</geometry>
			<material name="Cyan1">
	       		<color rgba="0 0.9 0.9 1.0"/>
			</material>
	   </visual>
	</link>
	
	<link name="link3"> <!-- cylinder1 -->
		<visual>
			<origin xyz="0 0 0" rpy="0 0 0"/>
			<geometry>
				<cylinder radius="0.05" length="0.2"/>
			</geometry>
	     	<material name="Yellow2">
				<color rgba="0.8 0.8 0 1.0"/>
			</material>
	   </visual>
	</link>
		
	<link name="link4"> <!-- ball1 -->
		<visual>
			<origin xyz="0 0 0" rpy="0 0 0"/>
			<geometry>
				<sphere radius="0.052"/>
			</geometry>
			<material name="Cyan1">
	       		<color rgba="0 0.9 0.9 1.0"/>
			</material>
	   </visual>
	</link>
	
	<link name="link5"> <!-- cylinder2 -->
		<visual>
			<origin xyz="0 0 0" rpy="0 0 0"/>
			<geometry>
				<cylinder radius="0.05" length="0.2"/>
			</geometry>
	     	<material name="Yellow2">
				<color rgba="0.8 0.8 0 1.0"/>
			</material>
	   </visual>
	</link>
		
	<link name="link6"> <!-- ball3 -->
		<visual>
			<origin xyz="0 0 0" rpy="0 0 0"/>
			<geometry>
				<sphere radius="0.052"/>
			</geometry>
			<material name="Cyan1">
	       		<color rgba="0 0.9 0.9 1.0"/>
			</material>
	   </visual>
	</link>
	
	<link name="link7"> <!-- cylinder3 -->
		<visual>
			<origin xyz="0 0 0" rpy="0 0 0"/>
			<geometry>
				<cylinder radius="0.05" length="0.2"/>
			</geometry>
	     	<material name="Yellow2">
				<color rgba="0.8 0.8 0 1.0"/>
			</material>
	   </visual>
	</link>

  <link name="link8"> <!-- gripper_base -->
  <inertial>
    <mass value="1"/>
    <inertia ixx="100" ixy="0" ixz="0" iyy="100" iyz="0" izz="100" />
    <origin/>
  </inertial>
    <visual>
      <geometry>
        <box size="0.105 .02 .025"/>
      </geometry>
      <origin rpy="0 0 0" xyz="0 -0.1 0"/>
      <material name="white">
        <color rgba="1 1 1 1"/>
      </material>
    </visual>
  <collision>
      <origin rpy="0 0 0" xyz="0 -0.1 0"/>
    <geometry>
        <box size="0.105 .02 .025"/>
    </geometry>
    <contact_coefficients mu="0" kp="1000.0" kd="1.0"/>
  </collision>
  </link>

 <link name="link9"> <!-- left_fingertip -->
  <inertial>
    <mass value="1"/>
    <inertia ixx="100" ixy="0" ixz="0" iyy="100" iyz="0" izz="100" />
    <origin/>
  </inertial>
    <visual>
      <geometry>
        <box size="0.025 .05 0.025"/>
      </geometry>
      <origin rpy="0 0 0" xyz="0 0 0"/>
      <material name="white">
        <color rgba="1 1 1 1"/>
      </material>
    </visual>
  <collision>
      <origin rpy="0 0 0" xyz="0 0 0"/>
    <geometry>
        <box size="0.025 .05 0.025"/>
    </geometry>
    <contact_coefficients mu="0" kp="1000.0" kd="1.0"/>
  </collision>
  </link>

    <link name="link10"> <!-- right fingertip -->
  <inertial>
    <mass value="1"/>
    <inertia ixx="100" ixy="0" ixz="0" iyy="100" iyz="0" izz="100" />
    <origin/>
  </inertial>
    <visual>
      <geometry>
        <box size="0.025 .05 0.025"/>
      </geometry>
      <origin rpy="0 0 0" xyz="0 0 0"/>
      <material name="white">
        <color rgba="1 1 1 1"/>
      </material>
    </visual>
  <collision>
     <origin rpy="0 0 0" xyz="0 0 0"/>
    <geometry>
        <box size="0.025 .05 0.025"/>
    </geometry>
    <contact_coefficients mu="0" kp="1000.0" kd="1.0"/>
  </collision>
  </link>
		
		
	
	<!-- * * * Joint Definitions * * * -->
	
	<joint name="joint0" type="revolute">  <!-- base -->
    	<parent link="link0"/>
    	<child link="link1"/>
    	<origin xyz="0 0 0.10" rpy="0 0 0"/>
    	<axis xyz="0 0 1"/>
    	<limit lower="-0.6" upper="0.6" effort="0" velocity="3"/>
  	</joint>
 
 	<joint name="joint1" type="revolute">  <!-- cylinder0 -->
    	<parent link="link1"/>
    	<child link="link2"/>
    	<origin xyz="0 0 0.1" rpy="0 0 0"/>
		<limit lower="0" upper="1.6" effort="10" velocity="3"/>
        <axis xyz="0 1 0"/>
	</joint>
	 
 	<joint name="joint2" type="fixed">  <!-- ball0 to cylinder0 -->
    	<parent link="link2"/>
    	<child link="link3"/>
    	<origin xyz="0 0 0.1" rpy="0 0 0"/>
        <axis xyz="0 0 1"/>
	</joint>
 
 	<joint name="joint3" type="revolute">  <!-- cylinder1 -->
    	<parent link="link3"/>
    	<child link="link4"/>
    	<origin xyz="0 0 0.1" rpy="0 0 0"/>
		<limit lower="-1.57" upper="1.57" effort="10" velocity="3"/>
        <axis xyz="0 1 0"/>
	</joint>
	 
 	<joint name="joint4" type="fixed">  <!-- ball1 to cylinder1 -->
    	<parent link="link4"/>
    	<child link="link5"/>
    	<origin xyz="0 0 0.1" rpy="0 0 0"/>
        <axis xyz="0 0 1"/>
	</joint>
 
 	<joint name="joint5" type="revolute">  <!-- cylinder2 -->
    	<parent link="link5"/>
    	<child link="link6"/>
    	<origin xyz="0 0 0.1" rpy="0 0 0"/>
		<limit lower="-1.57" upper="1.57" effort="10" velocity="3"/>
        <axis xyz="0 1 0"/>
	</joint>
	 
 	<joint name="joint6" type="fixed">  <!-- ball2 to cylinder2 -->
    	<parent link="link6"/>
    	<child link="link7"/>
    	<origin xyz="0 0 0.1" rpy="0 0 0"/>
        <axis xyz="0 0 1"/>
	</joint>
	 
 	<joint name="joint7" type="revolute">  <!-- gripper_base -->
    	<parent link="link7"/>
    	<child link="link8"/>
    	<origin xyz="0 0 0" rpy="-1.5708 0  0"/>
        <axis xyz="0 1 0"/>
    	<limit lower="-1.57" upper="1.57" effort="10" velocity="3"/>
	</joint>
 
  <joint name="joint8" type="prismatic">  <!-- gripper_base_to_right_fingertip -->
    <axis xyz="1 0 0"/>
    <limit effort="1.0" lower="-0.03" upper="0.0" velocity="0.5"/>
    <parent link="link8"/>
    <child link="link9"/>
    <origin xyz="0.04 -0.135 -0.0"/>
  </joint>

    <joint name="joint9" type="prismatic">  <!-- gripper_base_to_left_fingertip -->
    <axis xyz="1 0 0"/>
    <limit effort="1.0" lower="0" upper="0.03" velocity="0.5"/>
    <parent link="link8"/>
    <child link="link10"/>
    <origin xyz="-0.04 -0.135 0.0"/>
  </joint>

</robot>